Workbook
Name Acq_Financing_Type_Switch: 'Debt Input'!$F$3
Name acquisition_cost: Import!$C$50
Name adr: Import!$C$51
Name adr_pro_forma: Import!$C$52
Name AF_Amort_P_Adj: AF_Amort_Periods - AF_Interest_Only
Name AF_Amort_Periods: AF_Amort*12
Name AF_Amort_Periods: AF_Amort*12
Name AF_Annual_Debt_Service: AF_Loan_Payment*12
Name AF_CUMPRINC: IFERROR(CUMPRINC(AF_I_Adj,AF_Amort_P_Adj, AF_Orig_Loan_Amount,1, AF_Int_Only_Period,0),0)
Name AF_FV: FV(AF_I_Adj, AF_Orig_Term*12, AF_PMT, AF_Orig_Loan_Amount)
Name AF_I_Adj: (AF_Interest_Rate/AF_Rate_Compounding_Switch + 1) ^ (AF_Rate_Compounding_Switch/12)-1
Name AF_Int_Only_Period: AF_Rate_Period_Switch-(AF_Interest_Only/12 )*AF_Rate_Compounding_Switch
Name AF_IPMT: IPMT(AF_I_Adj,1,AF_Amort_P_Adj, AF_Orig_Loan_Amount,0)
Name AF_Loan_Constant: -AF_Loan_Payment/AF_Orig_Loan_Amount*12
Name AF_Loan_Due_Date: EDATE(AF_Origination_Date, AF_Orig_Term*12-1)
Name AF_Loan_Payment: IF(AF_Int_Only_Period<0, AF_IPMT,AF_PMT)
Name AF_PMT: PMT(AF_I_Adj, AF_Amort_P_Adj, AF_Orig_Loan_Amount)
Name AF_PPMT: PPMT(AF_I_Adj,1, AF_Amort_P_Adj, AF_Orig_Loan_Amount,0)
Name AF_Rate_Compounding_Switch: _xlfn.SWITCH(AF_Compounding_Switch, "Monthly", 12, "Semi-Annually", 2)
Name AF_Rate_Compounding_Switch: _xlfn.SWITCH(AF_Compounding_Switch, "Monthly", 12, "Semi-Annually", 2)
Name AF_Time_Remaining: ROUNDUP(YEARFRAC(AF_Origination_Date, AF_Loan_Due_Date)*12,0)+1
Name Annualized_Rents_OS_Type: 'Annualized Rents'!$C$1:$C$4
Name Annualized_Total_Rents: 'Annualized Rents'!$B$1:$B$4
Name buildable_sq_ft: Import!$C$36
Name buildable_units: Import!$C$37
Name cap_over_lease: Import!$C$59
Name cap_rate: Import!$C$2
Name cap_rate_pro_forma: Import!$C$3
Name CapEx_1: Input!$E$27
Name CapEx_10: Input!$N$27
Name CapEx_2: Input!$F$27
Name CapEx_3: Input!$G$27
Name CapEx_4: Input!$H$27
Name CapEx_5: Input!$I$27
Name CapEx_6: Input!$J$27
Name CapEx_7: Input!$K$27
Name CapEx_8: Input!$L$27
Name CapEx_9: Input!$M$27
Name cash_on_cash: Import!$C$14
Name cash_on_cash_pro_forma: Import!$C$15
Name Cost_of_Sale: Input!$B$30
Name Current_Amort: IF(Acq_Financing_Type_Switch="Financed - Assumed Loan", SED_Amort,NEW_Amort)
Name Current_GAR: 'Rent Roll Calculations'!$K$33
Name Current_Interest_Rate: IF(Acq_Financing_Type_Switch="Financed - Assumed Loan", SED_Interest_Rate,NEW_Interest_Rate)
Name Current_Loan_Balance: Calculations!$F$11
Name Current_Loan_Origination_Fee: Calculations!$F$26
Name Current_PMT: Calculations!$F$14
Name Current_Term: IF(Acq_Financing_Type_Switch="Financed - Assumed Loan", SED_Term,NEW_Term)
Name Date_of_Analysis: Input!$B$8
Name ddl_OpColumns: OFFSET(Calculations!$Y$3,5-Calculations!$Y$2,0,Calculations!$Y$2,1)
Name debt_service: Import!$C$4
Name debt_service_pro_forma: Import!$C$5
Name density: Import!$C$38
Name development_type: Import!$C$35
Name down_payment: Import!$C$6
Name Equity_Returns_Input: 'Equity Returns Input'!$B$12:$L$27
Name Equity_Returns_Input_Headers: 'Equity Returns Input'!$B$12:$L$12
Name Equity_Returns_List: 'Data Validation'!$L$1:$L$4
Name ER_Exchange: 'Equity Returns Input'!$B$12:$C$27
Name ER_Hold: 'Equity Returns Input'!$E$12:$F$27

Sheet Import
A1: Named Range | B1: UI Name | C1: Values | E1: Unit mix
A2: cap_rate | B2: Cap Rate | C2: =ROUND('Pricing Detail'!G13*100,2) -> 0 | E2: count | F2: unit_type | G2: size | H2: rent
A3: cap_rate_pro_forma | B3: Cap Rate (Pro Forma) | C3: ='Pricing Detail'!H13 -> 0
A4: debt_service | B4: Debt Service (Current) | C4: =ROUND('Pricing Detail'!N15,0) -> 0
A5: debt_service_pro_forma | B5: Debt Service (Pro Forma) | C5: =debt_service -> 0
A6: down_payment | B6: Down Payment | C6: =ROUND('Pricing Detail'!G5,0) -> 0
A7: net_operating_income | B7: Net Operating Income (Current) | C7: =ROUND('Pricing Detail'!N13,0) -> 0
A8: net_operating_income_pro_forma | B8: Net Operating Income (Pro Forma) | C8: ='Pricing Detail'!P13 -> 0
A9: operating_expenses | B9: Expenses (Current) | C9: =ROUND('Pricing Detail'!N12,0) -> 0
A10: operating_expenses_pro_forma | B10: Expenses (Pro Forma) | C10: ='Pricing Detail'!P12 -> 0
A11: principal_reduction_yr_1 | B11: Principal Reduction (Current) | C11: =ROUND('Pricing Detail'!N17,0) -> 0
A12: principal_reduction_pro_forma | B12: Principal Reduction (Pro Forma) | C12: ='Debt Input'!U31 -> 0
A13: sale_price | B13: Proposal Price / Listing Price | C13: =sale_price -> 0
A14: cash_on_cash | B14: Total Return $ (Current) | C14: =ROUND('Pricing Detail'!N18,0) -> 0
A15: cash_on_cash_pro_forma | B15: Total Return $ (Pro Forma) | C15: =ROUND('Pricing Detail'!P18,0) -> 0
A16: total_return | B16: Total Return % (Current) | C16: =ROUND('Pricing Detail'!M18*100,2) -> 0
A17: total_return_pro_forma | B17: Total Return % (Pro Forma) | C17: =ROUND('Pricing Detail'!O18*100,2) -> 0
A18: loan_type | B18: Loan Type | C18: =IF(Acq_Financing_Type_Switch="All Cash","All Cash",IF(Acq_Financing_Type_Switch="Financed - Assumed Loan","Loan Assumption","New Loan")) -> New Loan
A19: gross_scheduled_income | B19: Gross Potential Rent (Current) | C19: =ROUND('Pricing Detail'!N7,0) -> 0
A20: gross_scheduled_income_pro_forma | B20: Gross Potential Rent (Pro Forma) | C20: =ROUND('Pricing Detail'!P7,0) -> 0
A21: other_income | B21: Total Other Income (Current) | C21: =ROUND('Pricing Detail'!N10,0) -> 0
A22: other_income_pro_forma | B22: Total Other Income (Pro Forma) | C22: =ROUND('Pricing Detail'!P10,0) -> 0
A23: vacancy_cost | B23: Total Vacancy Cost (Current) | C23: =ROUND('Pricing Detail'!N8,0) -> 0
A24: vacancy_cost_pro_forma | B24: Total Vacancy Cost (Pro Forma) | C24: =ROUND('Pricing Detail'!P8,0) -> 0
A25: vacancy_percent | B25: Occupancy (Current)
A26: vacancy_percent_pro_forma | B26: Occupancy (Pro Forma)
A27: unit_count | B27: Number of Units
A28: exp_reimbursement | B28: Expense Reimbursement (Current)
A29: exp_reimbursement_pro_forma | B29: Expense Reimbursement (Pro Forma)
A30: leasing_commissions | B30: Leasing Commissions (Current)
A31: leasing_commissions_pro_forma | B31: Leasing Commissions (Pro Forma)
A32: tenant_improvements | B32: Tenant Improvements (Current) | E32: Tenant
A33: tenant_improvements_pro_forma | B33: Tenant Improvements (Pro Forma)
A34: number_of_lots | B34: Number of Lots | E34: tenant_name | F34: anchor_tenant | G34: tenant_type
A35: development_type | B35: Development Type
A36: buildable_sq_ft | B36: Buildable Square Feet
A37: buildable_units | B37: Buildable Units
A38: density | B38: Density
A39: floor_area_ratio | B39: Floor Area Ratio (FAR)
A40: home_inventory_cost | B40: Home Inventory Cost
...

Sheet Input
A1: Marcus & Millichap - NMHG - Financial Model
A5: Property Information | D5: {=IF(IFERROR(_xlfn.SEQUENCE(1,1,1,1),FALSE)=1, "This model is compatible with your version of Excel", "This model is NOT compatible with your version of Excel, please upgrade to Office 365")} -> This model is compatible with your version of Excel
A6: Price
A7: Priced or Unpriced Listing | B7: Priced
A8: Date of Analysis/Acquisition
A9: Proposal Purchase Price Increments
A10: Property Description Input
A11: Property Name
A12: Property Address
A13: Property City
A14: Property State
A15: Year Built
A16: Net Residual Value
A17: 10 year Cash Flow analysis/IRR calculation?
A18: Rent Roll
A19: Rent Roll Analysis Start Date
A20: Rent Roll Input Type
A21: Include Loss/Gain to Lease | Q21: =Input!B6 -> 0
A22: Total Units | S22: Initial Cash-
A23: Total Occupied Units | R23: Year One | S23: on-Cash | T23: Unleveraged | U23: Leveraged | V23: Price | W23: Price | X23: Year One
A24: Year 1 Rent Growth | Q24: Price | R24: Cap Rate | S24: Return | T24: IRR | U24: IRR | V24: Per SF | W24: Per Unit | X24: GRM
A25: Capital Expenditures (ie. Renovation Costs, major replacement, etc.) | D25: CapEx Schedule | R25: ='Pricing Detail'!$H$13 -> 0 | S25: ='Pricing Detail'!$G$15 -> 0 | T25: ='Cash Flow'!$P$45 -> 0 | U25: ='Cash Flow'!$P$46 -> 0 | V25: ='Pricing Detail'!$G$8 -> 0 | W25: ='Pricing Detail'!$G$7 -> 0 | X25: ='Pricing Detail'!H14 -> 0
A26: If using capital expenditure, then select Yes | D26: Years | E26: 1 | F26: 2 | G26: 3 | H26: 4 | I26: 5 | J26: 6 | K26: 7 | L26: 8 | M26: 9 | N26: 10 | Q26: =Q27+Price_Increments -> 0 | R26: 0 | S26: 0 | T26: 0 | U26: 0 | V26: 0 | W26: 0 | X26: 0
D27: Annual Amount | Q27: =Q28+Price_Increments -> 0 | R27: 0 | S27: 0 | T27: 0 | U27: 0 | V27: 0 | W27: 0 | X27: 0
A28: Net Residual Value | Q28: =Q29+Price_Increments -> 0 | R28: 0 | S28: 0 | T28: 0 | U28: 0 | V28: 0 | W28: 0 | X28: 0
A29: Exit Capitalization Rate | Q29: =Q30+Price_Increments -> 0 | R29: 0 | S29: 0 | T29: 0 | U29: 0 | V29: 0 | W29: 0 | X29: 0
A30: Cost of Sale | Q30: =Q31+Price_Increments -> 0 | R30: 0 | S30: 0 | T30: 0 | U30: 0 | V30: 0 | W30: 0 | X30: 0
Q31: {=Price} -> 0 | R31: 0 | S31: 0 | T31: 0 | U31: 0 | V31: 0 | W31: 0 | X31: 0
Q32: =Q31-Price_Increments -> 0 | R32: 0 | S32: 0 | T32: 0 | U32: 0 | V32: 0 | W32: 0 | X32: 0
Q33: =Q32-Price_Increments -> 0 | R33: 0 | S33: 0 | T33: 0 | U33: 0 | V33: 0 | W33: 0 | X33: 0
Q34: =Q33-Price_Increments -> 0 | R34: 0 | S34: 0 | T34: 0 | U34: 0 | V34: 0 | W34: 0 | X34: 0
Q35: =Q34-Price_Increments -> 0 | R35: 0 | S35: 0 | T35: 0 | U35: 0 | V35: 0 | W35: 0 | X35: 0
Q36: =Q35-Price_Increments -> 0 | R36: 0 | S36: 0 | T36: 0 | U36: 0 | V36: 0 | W36: 0 | X36: 0

Sheet Loan Amort Table
A3: Seller's Existing Debt | D3: =SED_Loan_Name -> 0 | J3: New Loan | M3: =NEW_Loan_Name -> 0 | S3: Mezzanine Loan | V3: =NEW_Loan_Name -> 0 | AB3: Refinanced Loan | AE3: =Refi_Loan_Name -> 0
A4: Loan | D4: Beginning | H4: Ending | J4: Loan | M4: Beginning | Q4: Ending | S4: Loan | V4: Beginning | Z4: Ending | AB4: Loan | AE4: Beginning | AI4: Ending
A5: Year | B5: PMT | C5: Date | D5: Loan Balance | E5: Payment | F5: Principal | G5: Interest | H5: Loan Balance | J5: Year | K5: PMT | L5: Date | M5: Loan Balance | N5: Payment | O5: Principal | P5: Interest | Q5: Loan Balance | S5: Year | T5: PMT | U5: Date | V5: Loan Balance | W5: Payment | X5: Principal | Y5: Interest | Z5: Loan Balance | AB5: Year | AC5: PMT | AD5: Date | AE5: Loan Balance | AF5: Payment | AG5: Principal | AH5: Interest | AI5: Loan Balance
A6: =IFERROR(ROUNDUP((DATEDIF(SED_Origination_Date,C6,"m")+1)/12,0),"") -> 1 | B6: =IF(C6>=SED_Begin_PMT,1,0) -> 1 | C6: =DATE(YEAR(SED_Origination_Date), MONTH(SED_Origination_Date),1) -> 1 | D6: =SED_Orig_Loan_Amount -> 0 | E6: =F6+G6 -> 0 | F6: =IFERROR(IF(OR(B6=0, C6>=Refi_Origination_Date),0, PPMT(SED_I_Adj,'Loan Amort Table'!B6,SED_Amort_Periods,SED_Orig_Loan_Amount)),0) -> 0 | G6: {=IFERROR(_xlfn.IFS(C6>=Refi_Origination_Date, 0, SED_Amort = 0, -D6 * SED_I_Adj, 1, IPMT(SED_I_Adj,IF(B6 = 0, 1, B6),SED_Amort_Periods,SED_Orig_Loan_Amount)),0)} -> 0 | H6: =D6+F6 -> 0 | J6: =IFERROR(ROUNDUP((DATEDIF(NEW_Origination_Date,L6,"m")+1)/12,0),"") -> 1 | K6: =IF(L6>=NEW_Begin_PMT,1,0) -> 1 | L6: =DATE(YEAR(NEW_Origination_Date), MONTH(NEW_Origination_Date),1) -> 1 | M6: =NEW_Orig_Loan_Amount -> 0 | N6: =O6+P6 -> 0 | O6: =IFERROR(IF(K6=0,0, PPMT(NEW_I_Adj,'Loan Amort Table'!K6,NEW_Amort_Periods,NEW_Orig_Loan_Amount)),0) -> 0 | P6: =IFERROR(IF(NEW_Amort = 0, -M6* NEW_I_Adj,IPMT(NEW_I_Adj,IF(K6 = 0, 1, K6),NEW_Amort_Periods,NEW_Orig_Loan_Amount)),0) -> 0 | Q6: =M6+O6 -> 0 | S6: =IFERROR(ROUNDUP((DATEDIF(Mezz_Origination_Date,U6,"m")+1)/12,0),"") -> 1 | T6: =IF(U6>=Mezz_Begin_PMT,1,0) -> 1 | U6: =DATE(YEAR(Mezz_Origination_Date), MONTH(Mezz_Origination_Date),1) -> 1 | V6: =Mezz_Loan_Balance -> 0 | W6: =X6+Y6 -> 0 | X6: =IFERROR(IF(OR(T6=0, U6>=Refi_Origination_Date),0, PPMT(Mezz_I_Adj,'Loan Amort Table'!T6,Mezz_Amort_Periods,Mezz_Orig_Loan_Amount)),0) -> 0 | Y6: {=IFERROR(_xlfn.IFS(U6>=Refi_Origination_Date,0, Mezz_Amort = 0, -V6 * Mezz_I_Adj, 1, IPMT(Mezz_I_Adj,IF(T6 = 0, 1, T6),Mezz_Amort_Periods,Mezz_Orig_Loan_Amount)),0)} -> 0 | Z6: =V6+X6 -> 0 | AB6: =IFERROR(ROUNDUP((DATEDIF(Refi_Origination_Date,AD6,"m")+1)/12,0),"") -> 1 | AC6: =IF(AD6>=Refi_Begin_PMT,1,0) -> 1 | AD6: =DATE(YEAR(Refi_Origination_Date), MONTH(Refi_Origination_Date),1) -> 1 | AE6: =Refi_Loan_Balance -> 0 | AF6: =AG6+AH6 -> 0 | AG6: =IFERROR(IF(AC6=0,0, PPMT(Refi_I_Adj,'Loan Amort Table'!AC6,Refi_Amort_Periods,Refi_Orig_Loan_Amount)),0) -> 0 | AH6: =IFERROR(IF(Refi_Amort = 0, -AE6 * Refi_I_Adj, IPMT(Refi_I_Adj,IF(AC6 = 0, 1, AC6),Refi_Amort_Periods,Refi_Orig_Loan_Amount)),0) -> 0 | AI6: =AE6+AG6 -> 0
A7: =IFERROR(ROUNDUP((DATEDIF(SED_Origination_Date,C7,"m")+1)/12,0),"") -> 1 | B7: =IF(C7<SED_Begin_PMT,0, B6+1) -> 2 | C7: =EDATE(C6,1) -> 32 | D7: =IF(C7>EDATE(DATE(YEAR(SED_Origination_Date)+ SED_Amort, MONTH(SED_Origination_Date), DAY(SED_Origination_Date)),SED_Interest_Only),0,H6) -> 0 | E7: =F7+G7 -> 0 | F7: =IFERROR(IF(OR(B7=0, C7>=Refi_Origination_Date),0, PPMT(SED_I_Adj,'Loan Amort Table'!B7,SED_Amort_Periods,SED_Orig_Loan_Amount)),0) -> 0 | G7: {=IFERROR(_xlfn.IFS(C7>=Refi_Origination_Date, 0, SED_Amort = 0, -D7 * SED_I_Adj, 1, IPMT(SED_I_Adj,IF(B7 = 0, 1, B7),SED_Amort_Periods,SED_Orig_Loan_Amount)),0)} -> 0 | H7: =D7+F7 -> 0 | J7: =IFERROR(ROUNDUP((DATEDIF(NEW_Origination_Date,L7,"m")+1)/12,0),"") -> 1 | K7: =IF(L7<NEW_Begin_PMT,0, K6+1) -> 2 | L7: =EDATE(L6,1) -> 32 | M7: =IF(L7>EDATE(DATE(YEAR(NEW_Origination_Date)+ NEW_Amort, MONTH(NEW_Origination_Date), DAY(NEW_Origination_Date)),NEW_Interest_Only),0,Q6) -> 0 | N7: =O7+P7 -> 0 | O7: =IFERROR(IF(K7=0,0, PPMT(NEW_I_Adj,'Loan Amort Table'!K7,NEW_Amort_Periods,NEW_Orig_Loan_Amount)),0) -> 0 | P7: =IFERROR(IF(NEW_Amort = 0, -M7* NEW_I_Adj,IPMT(NEW_I_Adj,IF(K7 = 0, 1, K7),NEW_Amort_Periods,NEW_Orig_Loan_Amount)),0) -> 0 | Q7: =M7+O7 -> 0 | S7: =IFERROR(ROUNDUP((DATEDIF(Mezz_Origination_Date,U7,"m")+1)/12,0),"") -> 1 | T7: =IF(U7<Mezz_Begin_PMT,0, T6+1) -> 2 | U7: =EDATE(U6,1) -> 32 | V7: =IF(U7>EDATE(DATE(YEAR(Mezz_Origination_Date)+ Mezz_Amort, MONTH(Mezz_Origination_Date), DAY(Mezz_Origination_Date)),Mezz_Interest_Only),0,Z6) -> 0 | W7: =X7+Y7 -> 0 | X7: =IFERROR(IF(OR(T7=0, U7>=Refi_Origination_Date),0, PPMT(Mezz_I_Adj,'Loan Amort Table'!T7,Mezz_Amort_Periods,Mezz_Orig_Loan_Amount)),0) -> 0 | Y7: {=IFERROR(_xlfn.IFS(U7>=Refi_Origination_Date,0, Mezz_Amort = 0, -V7 * Mezz_I_Adj, 1, IPMT(Mezz_I_Adj,IF(T7 = 0, 1, T7),Mezz_Amort_Periods,Mezz_Orig_Loan_Amount)),0)} -> 0 | Z7: =V7+X7 -> 0 | AB7: =IFERROR(ROUNDUP((DATEDIF(Refi_Origination_Date,AD7,"m")+1)/12,0),"") -> 1 | AC7: =IF(AD7<Refi_Begin_PMT,0, AC6+1) -> 2 | AD7: =EDATE(AD6,1) -> 32 | AE7: =IF(AD7>EDATE(DATE(YEAR(Refi_Origination_Date)+ Refi_Amort, MONTH(Refi_Origination_Date), DAY(Refi_Origination_Date)),Refi_Interest_Only),0,AI6) -> 0 | AF7: =AG7+AH7 -> 0 | AG7: =IFERROR(IF(AC7=0,0, PPMT(Refi_I_Adj,'Loan Amort Table'!AC7,Refi_Amort_Periods,Refi_Orig_Loan_Amount)),0) -> 0 | AH7: =IFERROR(IF(Refi_Amort = 0, -AE7 * Refi_I_Adj, IPMT(Refi_I_Adj,IF(AC7 = 0, 1, AC7),Refi_Amort_Periods,Refi_Orig_Loan_Amount)),0) -> 0 | AI7: =AE7+AG7 -> 0
A8: =IFERROR(ROUNDUP((DATEDIF(SED_Origination_Date,C8,"m")+1)/12,0),"") -> 1 | B8: =IF(C8<SED_Begin_PMT,0, B7+1) -> 3 | C8: =EDATE(C7,1) -> 61 | D8: =IF(C8>EDATE(DATE(YEAR(SED_Origination_Date)+ SED_Amort, MONTH(SED_Origination_Date), DAY(SED_Origination_Date)),SED_Interest_Only),0,H7) -> 0 | E8: =F8+G8 -> 0 | F8: =IFERROR(IF(OR(B8=0, C8>=Refi_Origination_Date),0, PPMT(SED_I_Adj,'Loan Amort Table'!B8,SED_Amort_Periods,SED_Orig_Loan_Amount)),0) -> 0 | G8: {=IFERROR(_xlfn.IFS(C8>=Refi_Origination_Date, 0, SED_Amort = 0, -D8 * SED_I_Adj, 1, IPMT(SED_I_Adj,IF(B8 = 0, 1, B8),SED_Amort_Periods,SED_Orig_Loan_Amount)),0)} -> 0 | H8: =D8+F8 -> 0 | J8: =IFERROR(ROUNDUP((DATEDIF(NEW_Origination_Date,L8,"m")+1)/12,0),"") -> 1 | K8: =IF(L8<NEW_Begin_PMT,0, K7+1) -> 3 | L8: =EDATE(L7,1) -> 61 | M8: =IF(L8>EDATE(DATE(YEAR(NEW_Origination_Date)+ NEW_Amort, MONTH(NEW_Origination_Date), DAY(NEW_Origination_Date)),NEW_Interest_Only),0,Q7) -> 0 | N8: =O8+P8 -> 0 | O8: =IFERROR(IF(K8=0,0, PPMT(NEW_I_Adj,'Loan Amort Table'!K8,NEW_Amort_Periods,NEW_Orig_Loan_Amount)),0) -> 0 | P8: =IFERROR(IF(NEW_Amort = 0, -M8* NEW_I_Adj,IPMT(NEW_I_Adj,IF(K8 = 0, 1, K8),NEW_Amort_Periods,NEW_Orig_Loan_Amount)),0) -> 0 | Q8: =M8+O8 -> 0 | S8: =IFERROR(ROUNDUP((DATEDIF(Mezz_Origination_Date,U8,"m")+1)/12,0),"") -> 1 | T8: =IF(U8<Mezz_Begin_PMT,0, T7+1) -> 3 | U8: =EDATE(U7,1) -> 61 | V8: =IF(U8>EDATE(DATE(YEAR(Mezz_Origination_Date)+ Mezz_Amort, MONTH(Mezz_Origination_Date), DAY(Mezz_Origination_Date)),Mezz_Interest_Only),0,Z7) -> 0 | W8: =X8+Y8 -> 0 | X8: =IFERROR(IF(OR(T8=0, U8>=Refi_Origination_Date),0, PPMT(Mezz_I_Adj,'Loan Amort Table'!T8,Mezz_Amort_Periods,Mezz_Orig_Loan_Amount)),0) -> 0 | Y8: {=IFERROR(_xlfn.IFS(U8>=Refi_Origination_Date,0, Mezz_Amort = 0, -V8 * Mezz_I_Adj, 1, IPMT(Mezz_I_Adj,IF(T8 = 0, 1, T8),Mezz_Amort_Periods,Mezz_Orig_Loan_Amount)),0)} -> 0 | Z8: =V8+X8 -> 0 | AB8: =IFERROR(ROUNDUP((DATEDIF(Refi_Origination_Date,AD8,"m")+1)/12,0),"") -> 1 | AC8: =IF(AD8<Refi_Begin_PMT,0, AC7+1) -> 3 | AD8: =EDATE(AD7,1) -> 61 | AE8: =IF(AD8>EDATE(DATE(YEAR(Refi_Origination_Date)+ Refi_Amort, MONTH(Refi_Origination_Date), DAY(Refi_Origination_Date)),Refi_Interest_Only),0,AI7) -> 0 | AF8: =AG8+AH8 -> 0 | AG8: =IFERROR(IF(AC8=0,0, PPMT(Refi_I_Adj,'Loan Amort Table'!AC8,Refi_Amort_Periods,Refi_Orig_Loan_Amount)),0) -> 0 | AH8: =IFERROR(IF(Refi_Amort = 0, -AE8 * Refi_I_Adj, IPMT(Refi_I_Adj,IF(AC8 = 0, 1, AC8),Refi_Amort_Periods,Refi_Orig_Loan_Amount)),0) -> 0 | AI8: =AE8+AG8 -> 0
A9: =IFERROR(ROUNDUP((DATEDIF(SED_Origination_Date,C9,"m")+1)/12,0),"") -> 1 | B9: =IF(C9<SED_Begin_PMT,0, B8+1) -> 4 | C9: =EDATE(C8,1) -> 92 | D9: =IF(C9>EDATE(DATE(YEAR(SED_Origination_Date)+ SED_Amort, MONTH(SED_Origination_Date), DAY(SED_Origination_Date)),SED_Interest_Only),0,H8) -> 0 | E9: =F9+G9 -> 0 | F9: =IFERROR(IF(OR(B9=0, C9>=Refi_Origination_Date),0, PPMT(SED_I_Adj,'Loan Amort Table'!B9,SED_Amort_Periods,SED_Orig_Loan_Amount)),0) -> 0 | G9: {=IFERROR(_xlfn.IFS(C9>=Refi_Origination_Date, 0, SED_Amort = 0, -D9 * SED_I_Adj, 1, IPMT(SED_I_Adj,IF(B9 = 0, 1, B9),SED_Amort_Periods,SED_Orig_Loan_Amount)),0)} -> 0 | H9: =D9+F9 -> 0 | J9: =IFERROR(ROUNDUP((DATEDIF(NEW_Origination_Date,L9,"m")+1)/12,0),"") -> 1 | K9: =IF(L9<NEW_Begin_PMT,0, K8+1) -> 4 | L9: =EDATE(L8,1) -> 92 | M9: =IF(L9>EDATE(DATE(YEAR(NEW_Origination_Date)+ NEW_Amort, MONTH(NEW_Origination_Date), DAY(NEW_Origination_Date)),NEW_Interest_Only),0,Q8) -> 0 | N9: =O9+P9 -> 0 | O9: =IFERROR(IF(K9=0,0, PPMT(NEW_I_Adj,'Loan Amort Table'!K9,NEW_Amort_Periods,NEW_Orig_Loan_Amount)),0) -> 0 | P9: =IFERROR(IF(NEW_Amort = 0, -M9* NEW_I_Adj,IPMT(NEW_I_Adj,IF(K9 = 0, 1, K9),NEW_Amort_Periods,NEW_Orig_Loan_Amount)),0) -> 0 | Q9: =M9+O9 -> 0 | S9: =IFERROR(ROUNDUP((DATEDIF(Mezz_Origination_Date,U9,"m")+1)/12,0),"") -> 1 | T9: =IF(U9<Mezz_Begin_PMT,0, T8+1) -> 4 | U9: =EDATE(U8,1) -> 92 | V9: =IF(U9>EDATE(DATE(YEAR(Mezz_Origination_Date)+ Mezz_Amort, MONTH(Mezz_Origination_Date), DAY(Mezz_Origination_Date)),Mezz_Interest_Only),0,Z8) -> 0 | W9: =X9+Y9 -> 0 | X9: =IFERROR(IF(OR(T9=0, U9>=Refi_Origination_Date),0, PPMT(Mezz_I_Adj,'Loan Amort Table'!T9,Mezz_Amort_Periods,Mezz_Orig_Loan_Amount)),0) -> 0 | Y9: {=IFERROR(_xlfn.IFS(U9>=Refi_Origination_Date,0, Mezz_Amort = 0, -V9 * Mezz_I_Adj, 1, IPMT(Mezz_I_Adj,IF(T9 = 0, 1, T9),Mezz_Amort_Periods,Mezz_Orig_Loan_Amount)),0)} -> 0 | Z9: =V9+X9 -> 0 | AB9: =IFERROR(ROUNDUP((DATEDIF(Refi_Origination_Date,AD9,"m")+1)/12,0),"") -> 1 | AC9: =IF(AD9<Refi_Begin_PMT,0, AC8+1) -> 4 | AD9: =EDATE(AD8,1) -> 92 | AE9: =IF(AD9>EDATE(DATE(YEAR(Refi_Origination_Date)+ Refi_Amort, MONTH(Refi_Origination_Date), DAY(Refi_Origination_Date)),Refi_Interest_Only),0,AI8) -> 0 | AF9: =AG9+AH9 -> 0 | AG9: =IFERROR(IF(AC9=0,0, PPMT(Refi_I_Adj,'Loan Amort Table'!AC9,Refi_Amort_Periods,Refi_Orig_Loan_Amount)),0) -> 0 | AH9: =IFERROR(IF(Refi_Amort = 0, -AE9 * Refi_I_Adj, IPMT(Refi_I_Adj,IF(AC9 = 0, 1, AC9),Refi_Amort_Periods,Refi_Orig_Loan_Amount)),0) -> 0 | AI9: =AE9+AG9 -> 0
A10: =IFERROR(ROUNDUP((DATEDIF(SED_Origination_Date,C10,"m")+1)/12,0),"") -> 1 | B10: =IF(C10<SED_Begin_PMT,0, B9+1) -> 5 | C10: =EDATE(C9,1) -> 122 | D10: =IF(C10>EDATE(DATE(YEAR(SED_Origination_Date)+ SED_Amort, MONTH(SED_Origination_Date), DAY(SED_Origination_Date)),SED_Interest_Only),0,H9) -> 0 | E10: =F10+G10 -> 0 | F10: =IFERROR(IF(OR(B10=0, C10>=Refi_Origination_Date),0, PPMT(SED_I_Adj,'Loan Amort Table'!B10,SED_Amort_Periods,SED_Orig_Loan_Amount)),0) -> 0 | G10: {=IFERROR(_xlfn.IFS(C10>=Refi_Origination_Date, 0, SED_Amort = 0, -D10 * SED_I_Adj, 1, IPMT(SED_I_Adj,IF(B10 = 0, 1, B10),SED_Amort_Periods,SED_Orig_Loan_Amount)),0)} -> 0 | H10: =D10+F10 -> 0 | J10: =IFERROR(ROUNDUP((DATEDIF(NEW_Origination_Date,L10,"m")+1)/12,0),"") -> 1 | K10: =IF(L10<NEW_Begin_PMT,0, K9+1) -> 5 | L10: =EDATE(L9,1) -> 122 | M10: =IF(L10>EDATE(DATE(YEAR(NEW_Origination_Date)+ NEW_Amort, MONTH(NEW_Origination_Date), DAY(NEW_Origination_Date)),NEW_Interest_Only),0,Q9) -> 0 | N10: =O10+P10 -> 0 | O10: =IFERROR(IF(K10=0,0, PPMT(NEW_I_Adj,'Loan Amort Table'!K10,NEW_Amort_Periods,NEW_Orig_Loan_Amount)),0) -> 0 | P10: =IFERROR(IF(NEW_Amort = 0, -M10* NEW_I_Adj,IPMT(NEW_I_Adj,IF(K10 = 0, 1, K10),NEW_Amort_Periods,NEW_Orig_Loan_Amount)),0) -> 0 | Q10: =M10+O10 -> 0 | S10: =IFERROR(ROUNDUP((DATEDIF(Mezz_Origination_Date,U10,"m")+1)/12,0),"") -> 1 | T10: =IF(U10<Mezz_Begin_PMT,0, T9+1) -> 5 | U10: =EDATE(U9,1) -> 122 | V10: =IF(U10>EDATE(DATE(YEAR(Mezz_Origination_Date)+ Mezz_Amort, MONTH(Mezz_Origination_Date), DAY(Mezz_Origination_Date)),Mezz_Interest_Only),0,Z9) -> 0 | W10: =X10+Y10 -> 0 | X10: =IFERROR(IF(OR(T10=0, U10>=Refi_Origination_Date),0, PPMT(Mezz_I_Adj,'Loan Amort Table'!T10,Mezz_Amort_Periods,Mezz_Orig_Loan_Amount)),0) -> 0 | Y10: {=IFERROR(_xlfn.IFS(U10>=Refi_Origination_Date,0, Mezz_Amort = 0, -V10 * Mezz_I_Adj, 1, IPMT(Mezz_I_Adj,IF(T10 = 0, 1, T10),Mezz_Amort_Periods,Mezz_Orig_Loan_Amount)),0)} -> 0 | Z10: =V10+X10 -> 0 | AB10: =IFERROR(ROUNDUP((DATEDIF(Refi_Origination_Date,AD10,"m")+1)/12,0),"") -> 1 | AC10: =IF(AD10<Refi_Begin_PMT,0, AC9+1) -> 5 | AD10: =EDATE(AD9,1) -> 122 | AE10: =IF(AD10>EDATE(DATE(YEAR(Refi_Origination_Date)+ Refi_Amort, MONTH(Refi_Origination_Date), DAY(Refi_Origination_Date)),Refi_Interest_Only),0,AI9) -> 0 | AF10: =AG10+AH10 -> 0 | AG10: =IFERROR(IF(AC10=0,0, PPMT(Refi_I_Adj,'Loan Amort Table'!AC10,Refi_Amort_Periods,Refi_Orig_Loan_Amount)),0) -> 0 | AH10: =IFERROR(IF(Refi_Amort = 0, -AE10 * Refi_I_Adj, IPMT(Refi_I_Adj,IF(AC10 = 0, 1, AC10),Refi_Amort_Periods,Refi_Orig_Loan_Amount)),0) -> 0 | AI10: =AE10+AG10 -> 0
A11: =IFERROR(ROUNDUP((DATEDIF(SED_Origination_Date,C11,"m")+1)/12,0),"") -> 1 | B11: =IF(C11<SED_Begin_PMT,0, B10+1) -> 6 | C11: =EDATE(C10,1) -> 153 | D11: =IF(C11>EDATE(DATE(YEAR(SED_Origination_Date)+ SED_Amort, MONTH(SED_Origination_Date), DAY(SED_Origination_Date)),SED_Interest_Only),0,H10) -> 0 | E11: =F11+G11 -> 0 | F11: =IFERROR(IF(OR(B11=0, C11>=Refi_Origination_Date),0, PPMT(SED_I_Adj,'Loan Amort Table'!B11,SED_Amort_Periods,SED_Orig_Loan_Amount)),0) -> 0 | G11: {=IFERROR(_xlfn.IFS(C11>=Refi_Origination_Date, 0, SED_Amort = 0, -D11 * SED_I_Adj, 1, IPMT(SED_I_Adj,IF(B11 = 0, 1, B11),SED_Amort_Periods,SED_Orig_Loan_Amount)),0)} -> 0 | H11: =D11+F11 -> 0 | J11: =IFERROR(ROUNDUP((DATEDIF(NEW_Origination_Date,L11,"m")+1)/12,0),"") -> 1 | K11: =IF(L11<NEW_Begin_PMT,0, K10+1) -> 6 | L11: =EDATE(L10,1) -> 153 | M11: =IF(L11>EDATE(DATE(YEAR(NEW_Origination_Date)+ NEW_Amort, MONTH(NEW_Origination_Date), DAY(NEW_Origination_Date)),NEW_Interest_Only),0,Q10) -> 0 | N11: =O11+P11 -> 0 | O11: =IFERROR(IF(K11=0,0, PPMT(NEW_I_Adj,'Loan Amort Table'!K11,NEW_Amort_Periods,NEW_Orig_Loan_Amount)),0) -> 0 | P11: =IFERROR(IF(NEW_Amort = 0, -M11* NEW_I_Adj,IPMT(NEW_I_Adj,IF(K11 = 0, 1, K11),NEW_Amort_Periods,NEW_Orig_Loan_Amount)),0) -> 0 | Q11: =M11+O11 -> 0 | S11: =IFERROR(ROUNDUP((DATEDIF(Mezz_Origination_Date,U11,"m")+1)/12,0),"") -> 1 | T11: =IF(U11<Mezz_Begin_PMT,0, T10+1) -> 6 | U11: =EDATE(U10,1) -> 153 | V11: =IF(U11>EDATE(DATE(YEAR(Mezz_Origination_Date)+ Mezz_Amort, MONTH(Mezz_Origination_Date), DAY(Mezz_Origination_Date)),Mezz_Interest_Only),0,Z10) -> 0 | W11: =X11+Y11 -> 0 | X11: =IFERROR(IF(OR(T11=0, U11>=Refi_Origination_Date),0, PPMT(Mezz_I_Adj,'Loan Amort Table'!T11,Mezz_Amort_Periods,Mezz_Orig_Loan_Amount)),0) -> 0 | Y11: {=IFERROR(_xlfn.IFS(U11>=Refi_Origination_Date,0, Mezz_Amort = 0, -V11 * Mezz_I_Adj, 1, IPMT(Mezz_I_Adj,IF(T11 = 0, 1, T11),Mezz_Amort_Periods,Mezz_Orig_Loan_Amount)),0)} -> 0 | Z11: =V11+X11 -> 0 | AB11: =IFERROR(ROUNDUP((DATEDIF(Refi_Origination_Date,AD11,"m")+1)/12,0),"") -> 1 | AC11: =IF(AD11<Refi_Begin_PMT,0, AC10+1) -> 6 | AD11: =EDATE(AD10,1) -> 153 | AE11: =IF(AD11>EDATE(DATE(YEAR(Refi_Origination_Date)+ Refi_Amort, MONTH(Refi_Origination_Date), DAY(Refi_Origination_Date)),Refi_Interest_Only),0,AI10) -> 0 | AF11: =AG11+AH11 -> 0 | AG11: =IFERROR(IF(AC11=0,0, PPMT(Refi_I_Adj,'Loan Amort Table'!AC11,Refi_Amort_Periods,Refi_Orig_Loan_Amount)),0) -> 0 | AH11: =IFERROR(IF(Refi_Amort = 0, -AE11 * Refi_I_Adj, IPMT(Refi_I_Adj,IF(AC11 = 0, 1, AC11),Refi_Amort_Periods,Refi_Orig_Loan_Amount)),0) -> 0 | AI11: =AE11+AG11 -> 0
A12: =IFERROR(ROUNDUP((DATEDIF(SED_Origination_Date,C12,"m")+1)/12,0),"") -> 1 | B12: =IF(C12<SED_Begin_PMT,0, B11+1) -> 7 | C12: =EDATE(C11,1) -> 183 | D12: =IF(C12>EDATE(DATE(YEAR(SED_Origination_Date)+ SED_Amort, MONTH(SED_Origination_Date), DAY(SED_Origination_Date)),SED_Interest_Only),0,H11) -> 0 | E12: =F12+G12 -> 0 | F12: =IFERROR(IF(OR(B12=0, C12>=Refi_Origination_Date),0, PPMT(SED_I_Adj,'Loan Amort Table'!B12,SED_Amort_Periods,SED_Orig_Loan_Amount)),0) -> 0 | G12: {=IFERROR(_xlfn.IFS(C12>=Refi_Origination_Date, 0, SED_Amort = 0, -D12 * SED_I_Adj, 1, IPMT(SED_I_Adj,IF(B12 = 0, 1, B12),SED_Amort_Periods,SED_Orig_Loan_Amount)),0)} -> 0 | H12: =D12+F12 -> 0 | J12: =IFERROR(ROUNDUP((DATEDIF(NEW_Origination_Date,L12,"m")+1)/12,0),"") -> 1 | K12: =IF(L12<NEW_Begin_PMT,0, K11+1) -> 7 | L12: =EDATE(L11,1) -> 183 | M12: =IF(L12>EDATE(DATE(YEAR(NEW_Origination_Date)+ NEW_Amort, MONTH(NEW_Origination_Date), DAY(NEW_Origination_Date)),NEW_Interest_Only),0,Q11) -> 0 | N12: =O12+P12 -> 0 | O12: =IFERROR(IF(K12=0,0, PPMT(NEW_I_Adj,'Loan Amort Table'!K12,NEW_Amort_Periods,NEW_Orig_Loan_Amount)),0) -> 0 | P12: =IFERROR(IF(NEW_Amort = 0, -M12* NEW_I_Adj,IPMT(NEW_I_Adj,IF(K12 = 0, 1, K12),NEW_Amort_Periods,NEW_Orig_Loan_Amount)),0) -> 0 | Q12: =M12+O12 -> 0 | S12: =IFERROR(ROUNDUP((DATEDIF(Mezz_Origination_Date,U12,"m")+1)/12,0),"") -> 1 | T12: =IF(U12<Mezz_Begin_PMT,0, T11+1) -> 7 | U12: =EDATE(U11,1) -> 183 | V12: =IF(U12>EDATE(DATE(YEAR(Mezz_Origination_Date)+ Mezz_Amort, MONTH(Mezz_Origination_Date), DAY(Mezz_Origination_Date)),Mezz_Interest_Only),0,Z11) -> 0 | W12: =X12+Y12 -> 0 | X12: =IFERROR(IF(OR(T12=0, U12>=Refi_Origination_Date),0, PPMT(Mezz_I_Adj,'Loan Amort Table'!T12,Mezz_Amort_Periods,Mezz_Orig_Loan_Amount)),0) -> 0 | Y12: {=IFERROR(_xlfn.IFS(U12>=Refi_Origination_Date,0, Mezz_Amort = 0, -V12 * Mezz_I_Adj, 1, IPMT(Mezz_I_Adj,IF(T12 = 0, 1, T12),Mezz_Amort_Periods,Mezz_Orig_Loan_Amount)),0)} -> 0 | Z12: =V12+X12 -> 0 | AB12: =IFERROR(ROUNDUP((DATEDIF(Refi_Origination_Date,AD12,"m")+1)/12,0),"") -> 1 | AC12: =IF(AD12<Refi_Begin_PMT,0, AC11+1) -> 7 | AD12: =EDATE(AD11,1) -> 183 | AE12: =IF(AD12>EDATE(DATE(YEAR(Refi_Origination_Date)+ Refi_Amort, MONTH(Refi_Origination_Date), DAY(Refi_Origination_Date)),Refi_Interest_Only),0,AI11) -> 0 | AF12: =AG12+AH12 -> 0 | AG12: =IFERROR(IF(AC12=0,0, PPMT(Refi_I_Adj,'Loan Amort Table'!AC12,Refi_Amort_Periods,Refi_Orig_Loan_Amount)),0) -> 0 | AH12: =IFERROR(IF(Refi_Amort = 0, -AE12 * Refi_I_Adj, IPMT(Refi_I_Adj,IF(AC12 = 0, 1, AC12),Refi_Amort_Periods,Refi_Orig_Loan_Amount)),0) -> 0 | AI12: =AE12+AG12 -> 0
A13: =IFERROR(ROUNDUP((DATEDIF(SED_Origination_Date,C13,"m")+1)/12,0),"") -> 1 | B13: =IF(C13<SED_Begin_PMT,0, B12+1) -> 8 | C13: =EDATE(C12,1) -> 214 | D13: =IF(C13>EDATE(DATE(YEAR(SED_Origination_Date)+ SED_Amort, MONTH(SED_Origination_Date), DAY(SED_Origination_Date)),SED_Interest_Only),0,H12) -> 0 | E13: =F13+G13 -> 0 | F13: =IFERROR(IF(OR(B13=0, C13>=Refi_Origination_Date),0, PPMT(SED_I_Adj,'Loan Amort Table'!B13,SED_Amort_Periods,SED_Orig_Loan_Amount)),0) -> 0 | G13: {=IFERROR(_xlfn.IFS(C13>=Refi_Origination_Date, 0, SED_Amort = 0, -D13 * SED_I_Adj, 1, IPMT(SED_I_Adj,IF(B13 = 0, 1, B13),SED_Amort_Periods,SED_Orig_Loan_Amount)),0)} -> 0 | H13: =D13+F13 -> 0 | J13: =IFERROR(ROUNDUP((DATEDIF(NEW_Origination_Date,L13,"m")+1)/12,0),"") -> 1 | K13: =IF(L13<NEW_Begin_PMT,0, K12+1) -> 8 | L13: =EDATE(L12,1) -> 214 | M13: =IF(L13>EDATE(DATE(YEAR(NEW_Origination_Date)+ NEW_Amort, MONTH(NEW_Origination_Date), DAY(NEW_Origination_Date)),NEW_Interest_Only),0,Q12) -> 0 | N13: =O13+P13 -> 0 | O13: =IFERROR(IF(K13=0,0, PPMT(NEW_I_Adj,'Loan Amort Table'!K13,NEW_Amort_Periods,NEW_Orig_Loan_Amount)),0) -> 0 | P13: =IFERROR(IF(NEW_Amort = 0, -M13* NEW_I_Adj,IPMT(NEW_I_Adj,IF(K13 = 0, 1, K13),NEW_Amort_Periods,NEW_Orig_Loan_Amount)),0) -> 0 | Q13: =M13+O13 -> 0 | S13: =IFERROR(ROUNDUP((DATEDIF(Mezz_Origination_Date,U13,"m")+1)/12,0),"") -> 1 | T13: =IF(U13<Mezz_Begin_PMT,0, T12+1) -> 8 | U13: =EDATE(U12,1) -> 214 | V13: =IF(U13>EDATE(DATE(YEAR(Mezz_Origination_Date)+ Mezz_Amort, MONTH(Mezz_Origination_Date), DAY(Mezz_Origination_Date)),Mezz_Interest_Only),0,Z12) -> 0 | W13: =X13+Y13 -> 0 | X13: =IFERROR(IF(OR(T13=0, U13>=Refi_Origination_Date),0, PPMT(Mezz_I_Adj,'Loan Amort Table'!T13,Mezz_Amort_Periods,Mezz_Orig_Loan_Amount)),0) -> 0 | Y13: {=IFERROR(_xlfn.IFS(U13>=Refi_Origination_Date,0, Mezz_Amort = 0, -V13 * Mezz_I_Adj, 1, IPMT(Mezz_I_Adj,IF(T13 = 0, 1, T13),Mezz_Amort_Periods,Mezz_Orig_Loan_Amount)),0)} -> 0 | Z13: =V13+X13 -> 0 | AB13: =IFERROR(ROUNDUP((DATEDIF(Refi_Origination_Date,AD13,"m")+1)/12,0),"") -> 1 | AC13: =IF(AD13<Refi_Begin_PMT,0, AC12+1) -> 8 | AD13: =EDATE(AD12,1) -> 214 | AE13: =IF(AD13>EDATE(DATE(YEAR(Refi_Origination_Date)+ Refi_Amort, MONTH(Refi_Origination_Date), DAY(Refi_Origination_Date)),Refi_Interest_Only),0,AI12) -> 0 | AF13: =AG13+AH13 -> 0 | AG13: =IFERROR(IF(AC13=0,0, PPMT(Refi_I_Adj,'Loan Amort Table'!AC13,Refi_Amort_Periods,Refi_Orig_Loan_Amount)),0) -> 0 | AH13: =IFERROR(IF(Refi_Amort = 0, -AE13 * Refi_I_Adj, IPMT(Refi_I_Adj,IF(AC13 = 0, 1, AC13),Refi_Amort_Periods,Refi_Orig_Loan_Amount)),0) -> 0 | AI13: =AE13+AG13 -> 0
A14: =IFERROR(ROUNDUP((DATEDIF(SED_Origination_Date,C14,"m")+1)/12,0),"") -> 1 | B14: =IF(C14<SED_Begin_PMT,0, B13+1) -> 9 | C14: =EDATE(C13,1) -> 245 | D14: =IF(C14>EDATE(DATE(YEAR(SED_Origination_Date)+ SED_Amort, MONTH(SED_Origination_Date), DAY(SED_Origination_Date)),SED_Interest_Only),0,H13) -> 0 | E14: =F14+G14 -> 0 | F14: =IFERROR(IF(OR(B14=0, C14>=Refi_Origination_Date),0, PPMT(SED_I_Adj,'Loan Amort Table'!B14,SED_Amort_Periods,SED_Orig_Loan_Amount)),0) -> 0 | G14: {=IFERROR(_xlfn.IFS(C14>=Refi_Origination_Date, 0, SED_Amort = 0, -D14 * SED_I_Adj, 1, IPMT(SED_I_Adj,IF(B14 = 0, 1, B14),SED_Amort_Periods,SED_Orig_Loan_Amount)),0)} -> 0 | H14: =D14+F14 -> 0 | J14: =IFERROR(ROUNDUP((DATEDIF(NEW_Origination_Date,L14,"m")+1)/12,0),"") -> 1 | K14: =IF(L14<NEW_Begin_PMT,0, K13+1) -> 9 | L14: =EDATE(L13,1) -> 245 | M14: =IF(L14>EDATE(DATE(YEAR(NEW_Origination_Date)+ NEW_Amort, MONTH(NEW_Origination_Date), DAY(NEW_Origination_Date)),NEW_Interest_Only),0,Q13) -> 0 | N14: =O14+P14 -> 0 | O14: =IFERROR(IF(K14=0,0, PPMT(NEW_I_Adj,'Loan Amort Table'!K14,NEW_Amort_Periods,NEW_Orig_Loan_Amount)),0) -> 0 | P14: =IFERROR(IF(NEW_Amort = 0, -M14* NEW_I_Adj,IPMT(NEW_I_Adj,IF(K14 = 0, 1, K14),NEW_Amort_Periods,NEW_Orig_Loan_Amount)),0) -> 0 | Q14: =M14+O14 -> 0 | S14: =IFERROR(ROUNDUP((DATEDIF(Mezz_Origination_Date,U14,"m")+1)/12,0),"") -> 1 | T14: =IF(U14<Mezz_Begin_PMT,0, T13+1) -> 9 | U14: =EDATE(U13,1) -> 245 | V14: =IF(U14>EDATE(DATE(YEAR(Mezz_Origination_Date)+ Mezz_Amort, MONTH(Mezz_Origination_Date), DAY(Mezz_Origination_Date)),Mezz_Interest_Only),0,Z13) -> 0 | W14: =X14+Y14 -> 0 | X14: =IFERROR(IF(OR(T14=0, U14>=Refi_Origination_Date),0, PPMT(Mezz_I_Adj,'Loan Amort Table'!T14,Mezz_Amort_Periods,Mezz_Orig_Loan_Amount)),0) -> 0 | Y14: {=IFERROR(_xlfn.IFS(U14>=Refi_Origination_Date,0, Mezz_Amort = 0, -V14 * Mezz_I_Adj, 1, IPMT(Mezz_I_Adj,IF(T14 = 0, 1, T14),Mezz_Amort_Periods,Mezz_Orig_Loan_Amount)),0)} -> 0 | Z14: =V14+X14 -> 0 | AB14: =IFERROR(ROUNDUP((DATEDIF(Refi_Origination_Date,AD14,"m")+1)/12,0),"") -> 1 | AC14: =IF(AD14<Refi_Begin_PMT,0, AC13+1) -> 9 | AD14: =EDATE(AD13,1) -> 245 | AE14: =IF(AD14>EDATE(DATE(YEAR(Refi_Origination_Date)+ Refi_Amort, MONTH(Refi_Origination_Date), DAY(Refi_Origination_Date)),Refi_Interest_Only),0,AI13) -> 0 | AF14: =AG14+AH14 -> 0 | AG14: =IFERROR(IF(AC14=0,0, PPMT(Refi_I_Adj,'Loan Amort Table'!AC14,Refi_Amort_Periods,Refi_Orig_Loan_Amount)),0) -> 0 | AH14: =IFERROR(IF(Refi_Amort = 0, -AE14 * Refi_I_Adj, IPMT(Refi_I_Adj,IF(AC14 = 0, 1, AC14),Refi_Amort_Periods,Refi_Orig_Loan_Amount)),0) -> 0 | AI14: =AE14+AG14 -> 0
A15: =IFERROR(ROUNDUP((DATEDIF(SED_Origination_Date,C15,"m")+1)/12,0),"") -> 1 | B15: =IF(C15<SED_Begin_PMT,0, B14+1) -> 10 | C15: =EDATE(C14,1) -> 275 | D15: =IF(C15>EDATE(DATE(YEAR(SED_Origination_Date)+ SED_Amort, MONTH(SED_Origination_Date), DAY(SED_Origination_Date)),SED_Interest_Only),0,H14) -> 0 | E15: =F15+G15 -> 0 | F15: =IFERROR(IF(OR(B15=0, C15>=Refi_Origination_Date),0, PPMT(SED_I_Adj,'Loan Amort Table'!B15,SED_Amort_Periods,SED_Orig_Loan_Amount)),0) -> 0 | G15: {=IFERROR(_xlfn.IFS(C15>=Refi_Origination_Date, 0, SED_Amort = 0, -D15 * SED_I_Adj, 1, IPMT(SED_I_Adj,IF(B15 = 0, 1, B15),SED_Amort_Periods,SED_Orig_Loan_Amount)),0)} -> 0 | H15: =D15+F15 -> 0 | J15: =IFERROR(ROUNDUP((DATEDIF(NEW_Origination_Date,L15,"m")+1)/12,0),"") -> 1 | K15: =IF(L15<NEW_Begin_PMT,0, K14+1) -> 10 | L15: =EDATE(L14,1) -> 275 | M15: =IF(L15>EDATE(DATE(YEAR(NEW_Origination_Date)+ NEW_Amort, MONTH(NEW_Origination_Date), DAY(NEW_Origination_Date)),NEW_Interest_Only),0,Q14) -> 0 | N15: =O15+P15 -> 0 | O15: =IFERROR(IF(K15=0,0, PPMT(NEW_I_Adj,'Loan Amort Table'!K15,NEW_Amort_Periods,NEW_Orig_Loan_Amount)),0) -> 0 | P15: =IFERROR(IF(NEW_Amort = 0, -M15* NEW_I_Adj,IPMT(NEW_I_Adj,IF(K15 = 0, 1, K15),NEW_Amort_Periods,NEW_Orig_Loan_Amount)),0) -> 0 | Q15: =M15+O15 -> 0 | S15: =IFERROR(ROUNDUP((DATEDIF(Mezz_Origination_Date,U15,"m")+1)/12,0),"") -> 1 | T15: =IF(U15<Mezz_Begin_PMT,0, T14+1) -> 10 | U15: =EDATE(U14,1) -> 275 | V15: =IF(U15>EDATE(DATE(YEAR(Mezz_Origination_Date)+ Mezz_Amort, MONTH(Mezz_Origination_Date), DAY(Mezz_Origination_Date)),Mezz_Interest_Only),0,Z14) -> 0 | W15: =X15+Y15 -> 0 | X15: =IFERROR(IF(OR(T15=0, U15>=Refi_Origination_Date),0, PPMT(Mezz_I_Adj,'Loan Amort Table'!T15,Mezz_Amort_Periods,Mezz_Orig_Loan_Amount)),0) -> 0 | Y15: {=IFERROR(_xlfn.IFS(U15>=Refi_Origination_Date,0, Mezz_Amort = 0, -V15 * Mezz_I_Adj, 1, IPMT(Mezz_I_Adj,IF(T15 = 0, 1, T15),Mezz_Amort_Periods,Mezz_Orig_Loan_Amount)),0)} -> 0 | Z15: =V15+X15 -> 0 | AB15: =IFERROR(ROUNDUP((DATEDIF(Refi_Origination_Date,AD15,"m")+1)/12,0),"") -> 1 | AC15: =IF(AD15<Refi_Begin_PMT,0, AC14+1) -> 10 | AD15: =EDATE(AD14,1) -> 275 | AE15: =IF(AD15>EDATE(DATE(YEAR(Refi_Origination_Date)+ Refi_Amort, MONTH(Refi_Origination_Date), DAY(Refi_Origination_Date)),Refi_Interest_Only),0,AI14) -> 0 | AF15: =AG15+AH15 -> 0 | AG15: =IFERROR(IF(AC15=0,0, PPMT(Refi_I_Adj,'Loan Amort Table'!AC15,Refi_Amort_Periods,Refi_Orig_Loan_Amount)),0) -> 0 | AH15: =IFERROR(IF(Refi_Amort = 0, -AE15 * Refi_I_Adj, IPMT(Refi_I_Adj,IF(AC15 = 0, 1, AC15),Refi_Amort_Periods,Refi_Orig_Loan_Amount)),0) -> 0 | AI15: =AE15+AG15 -> 0
A16: =IFERROR(ROUNDUP((DATEDIF(SED_Origination_Date,C16,"m")+1)/12,0),"") -> 1 | B16: =IF(C16<SED_Begin_PMT,0, B15+1) -> 11 | C16: =EDATE(C15,1) -> 306 | D16: =IF(C16>EDATE(DATE(YEAR(SED_Origination_Date)+ SED_Amort, MONTH(SED_Origination_Date), DAY(SED_Origination_Date)),SED_Interest_Only),0,H15) -> 0 | E16: =F16+G16 -> 0 | F16: =IFERROR(IF(OR(B16=0, C16>=Refi_Origination_Date),0, PPMT(SED_I_Adj,'Loan Amort Table'!B16,SED_Amort_Periods,SED_Orig_Loan_Amount)),0) -> 0 | G16: {=IFERROR(_xlfn.IFS(C16>=Refi_Origination_Date, 0, SED_Amort = 0, -D16 * SED_I_Adj, 1, IPMT(SED_I_Adj,IF(B16 = 0, 1, B16),SED_Amort_Periods,SED_Orig_Loan_Amount)),0)} -> 0 | H16: =D16+F16 -> 0 | J16: =IFERROR(ROUNDUP((DATEDIF(NEW_Origination_Date,L16,"m")+1)/12,0),"") -> 1 | K16: =IF(L16<NEW_Begin_PMT,0, K15+1) -> 11 | L16: =EDATE(L15,1) -> 306 | M16: =IF(L16>EDATE(DATE(YEAR(NEW_Origination_Date)+ NEW_Amort, MONTH(NEW_Origination_Date), DAY(NEW_Origination_Date)),NEW_Interest_Only),0,Q15) -> 0 | N16: =O16+P16 -> 0 | O16: =IFERROR(IF(K16=0,0, PPMT(NEW_I_Adj,'Loan Amort Table'!K16,NEW_Amort_Periods,NEW_Orig_Loan_Amount)),0) -> 0 | P16: =IFERROR(IF(NEW_Amort = 0, -M16* NEW_I_Adj,IPMT(NEW_I_Adj,IF(K16 = 0, 1, K16),NEW_Amort_Periods,NEW_Orig_Loan_Amount)),0) -> 0 | Q16: =M16+O16 -> 0 | S16: =IFERROR(ROUNDUP((DATEDIF(Mezz_Origination_Date,U16,"m")+1)/12,0),"") -> 1 | T16: =IF(U16<Mezz_Begin_PMT,0, T15+1) -> 11 | U16: =EDATE(U15,1) -> 306 | V16: =IF(U16>EDATE(DATE(YEAR(Mezz_Origination_Date)+ Mezz_Amort, MONTH(Mezz_Origination_Date), DAY(Mezz_Origination_Date)),Mezz_Interest_Only),0,Z15) -> 0 | W16: =X16+Y16 -> 0 | X16: =IFERROR(IF(OR(T16=0, U16>=Refi_Origination_Date),0, PPMT(Mezz_I_Adj,'Loan Amort Table'!T16,Mezz_Amort_Periods,Mezz_Orig_Loan_Amount)),0) -> 0 | Y16: {=IFERROR(_xlfn.IFS(U16>=Refi_Origination_Date,0, Mezz_Amort = 0, -V16 * Mezz_I_Adj, 1, IPMT(Mezz_I_Adj,IF(T16 = 0, 1, T16),Mezz_Amort_Periods,Mezz_Orig_Loan_Amount)),0)} -> 0 | Z16: =V16+X16 -> 0 | AB16: =IFERROR(ROUNDUP((DATEDIF(Refi_Origination_Date,AD16,"m")+1)/12,0),"") -> 1 | AC16: =IF(AD16<Refi_Begin_PMT,0, AC15+1) -> 11 | AD16: =EDATE(AD15,1) -> 306 | AE16: =IF(AD16>EDATE(DATE(YEAR(Refi_Origination_Date)+ Refi_Amort, MONTH(Refi_Origination_Date), DAY(Refi_Origination_Date)),Refi_Interest_Only),0,AI15) -> 0 | AF16: =AG16+AH16 -> 0 | AG16: =IFERROR(IF(AC16=0,0, PPMT(Refi_I_Adj,'Loan Amort Table'!AC16,Refi_Amort_Periods,Refi_Orig_Loan_Amount)),0) -> 0 | AH16: =IFERROR(IF(Refi_Amort = 0, -AE16 * Refi_I_Adj, IPMT(Refi_I_Adj,IF(AC16 = 0, 1, AC16),Refi_Amort_Periods,Refi_Orig_Loan_Amount)),0) -> 0 | AI16: =AE16+AG16 -> 0
A17: =IFERROR(ROUNDUP((DATEDIF(SED_Origination_Date,C17,"m")+1)/12,0),"") -> 1 | B17: =IF(C17<SED_Begin_PMT,0, B16+1) -> 12 | C17: =EDATE(C16,1) -> 336 | D17: =IF(C17>EDATE(DATE(YEAR(SED_Origination_Date)+ SED_Amort, MONTH(SED_Origination_Date), DAY(SED_Origination_Date)),SED_Interest_Only),0,H16) -> 0 | E17: =F17+G17 -> 0 | F17: =IFERROR(IF(OR(B17=0, C17>=Refi_Origination_Date),0, PPMT(SED_I_Adj,'Loan Amort Table'!B17,SED_Amort_Periods,SED_Orig_Loan_Amount)),0) -> 0 | G17: {=IFERROR(_xlfn.IFS(C17>=Refi_Origination_Date, 0, SED_Amort = 0, -D17 * SED_I_Adj, 1, IPMT(SED_I_Adj,IF(B17 = 0, 1, B17),SED_Amort_Periods,SED_Orig_Loan_Amount)),0)} -> 0 | H17: =D17+F17 -> 0 | J17: =IFERROR(ROUNDUP((DATEDIF(NEW_Origination_Date,L17,"m")+1)/12,0),"") -> 1 | K17: =IF(L17<NEW_Begin_PMT,0, K16+1) -> 12 | L17: =EDATE(L16,1) -> 336 | M17: =IF(L17>EDATE(DATE(YEAR(NEW_Origination_Date)+ NEW_Amort, MONTH(NEW_Origination_Date), DAY(NEW_Origination_Date)),NEW_Interest_Only),0,Q16) -> 0 | N17: =O17+P17 -> 0 | O17: =IFERROR(IF(K17=0,0, PPMT(NEW_I_Adj,'Loan Amort Table'!K17,NEW_Amort_Periods,NEW_Orig_Loan_Amount)),0) -> 0 | P17: =IFERROR(IF(NEW_Amort = 0, -M17* NEW_I_Adj,IPMT(NEW_I_Adj,IF(K17 = 0, 1, K17),NEW_Amort_Periods,NEW_Orig_Loan_Amount)),0) -> 0 | Q17: =M17+O17 -> 0 | S17: =IFERROR(ROUNDUP((DATEDIF(Mezz_Origination_Date,U17,"m")+1)/12,0),"") -> 1 | T17: =IF(U17<Mezz_Begin_PMT,0, T16+1) -> 12 | U17: =EDATE(U16,1) -> 336 | V17: =IF(U17>EDATE(DATE(YEAR(Mezz_Origination_Date)+ Mezz_Amort, MONTH(Mezz_Origination_Date), DAY(Mezz_Origination_Date)),Mezz_Interest_Only),0,Z16) -> 0 | W17: =X17+Y17 -> 0 | X17: =IFERROR(IF(OR(T17=0, U17>=Refi_Origination_Date),0, PPMT(Mezz_I_Adj,'Loan Amort Table'!T17,Mezz_Amort_Periods,Mezz_Orig_Loan_Amount)),0) -> 0 | Y17: {=IFERROR(_xlfn.IFS(U17>=Refi_Origination_Date,0, Mezz_Amort = 0, -V17 * Mezz_I_Adj, 1, IPMT(Mezz_I_Adj,IF(T17 = 0, 1, T17),Mezz_Amort_Periods,Mezz_Orig_Loan_Amount)),0)} -> 0 | Z17: =V17+X17 -> 0 | AB17: =IFERROR(ROUNDUP((DATEDIF(Refi_Origination_Date,AD17,"m")+1)/12,0),"") -> 1 | AC17: =IF(AD17<Refi_Begin_PMT,0, AC16+1) -> 12 | AD17: =EDATE(AD16,1) -> 336 | AE17: =IF(AD17>EDATE(DATE(YEAR(Refi_Origination_Date)+ Refi_Amort, MONTH(Refi_Origination_Date), DAY(Refi_Origination_Date)),Refi_Interest_Only),0,AI16) -> 0 | AF17: =AG17+AH17 -> 0 | AG17: =IFERROR(IF(AC17=0,0, PPMT(Refi_I_Adj,'Loan Amort Table'!AC17,Refi_Amort_Periods,Refi_Orig_Loan_Amount)),0) -> 0 | AH17: =IFERROR(IF(Refi_Amort = 0, -AE17 * Refi_I_Adj, IPMT(Refi_I_Adj,IF(AC17 = 0, 1, AC17),Refi_Amort_Periods,Refi_Orig_Loan_Amount)),0) -> 0 | AI17: =AE17+AG17 -> 0
A18: =IFERROR(ROUNDUP((DATEDIF(SED_Origination_Date,C18,"m")+1)/12,0),"") -> 2 | B18: =IF(C18<SED_Begin_PMT,0, B17+1) -> 13 | C18: =EDATE(C17,1) -> 367 | D18: =IF(C18>EDATE(DATE(YEAR(SED_Origination_Date)+ SED_Amort, MONTH(SED_Origination_Date), DAY(SED_Origination_Date)),SED_Interest_Only),0,H17) -> 0 | E18: =F18+G18 -> 0 | F18: =IFERROR(IF(OR(B18=0, C18>=Refi_Origination_Date),0, PPMT(SED_I_Adj,'Loan Amort Table'!B18,SED_Amort_Periods,SED_Orig_Loan_Amount)),0) -> 0 | G18: {=IFERROR(_xlfn.IFS(C18>=Refi_Origination_Date, 0, SED_Amort = 0, -D18 * SED_I_Adj, 1, IPMT(SED_I_Adj,IF(B18 = 0, 1, B18),SED_Amort_Periods,SED_Orig_Loan_Amount)),0)} -> 0 | H18: =D18+F18 -> 0 | J18: =IFERROR(ROUNDUP((DATEDIF(NEW_Origination_Date,L18,"m")+1)/12,0),"") -> 2 | K18: =IF(L18<NEW_Begin_PMT,0, K17+1) -> 13 | L18: =EDATE(L17,1) -> 367 | M18: =IF(L18>EDATE(DATE(YEAR(NEW_Origination_Date)+ NEW_Amort, MONTH(NEW_Origination_Date), DAY(NEW_Origination_Date)),NEW_Interest_Only),0,Q17) -> 0 | N18: =O18+P18 -> 0 | O18: =IFERROR(IF(K18=0,0, PPMT(NEW_I_Adj,'Loan Amort Table'!K18,NEW_Amort_Periods,NEW_Orig_Loan_Amount)),0) -> 0 | P18: =IFERROR(IF(NEW_Amort = 0, -M18* NEW_I_Adj,IPMT(NEW_I_Adj,IF(K18 = 0, 1, K18),NEW_Amort_Periods,NEW_Orig_Loan_Amount)),0) -> 0 | Q18: =M18+O18 -> 0 | S18: =IFERROR(ROUNDUP((DATEDIF(Mezz_Origination_Date,U18,"m")+1)/12,0),"") -> 2 | T18: =IF(U18<Mezz_Begin_PMT,0, T17+1) -> 13 | U18: =EDATE(U17,1) -> 367 | V18: =IF(U18>EDATE(DATE(YEAR(Mezz_Origination_Date)+ Mezz_Amort, MONTH(Mezz_Origination_Date), DAY(Mezz_Origination_Date)),Mezz_Interest_Only),0,Z17) -> 0 | W18: =X18+Y18 -> 0 | X18: =IFERROR(IF(OR(T18=0, U18>=Refi_Origination_Date),0, PPMT(Mezz_I_Adj,'Loan Amort Table'!T18,Mezz_Amort_Periods,Mezz_Orig_Loan_Amount)),0) -> 0 | Y18: {=IFERROR(_xlfn.IFS(U18>=Refi_Origination_Date,0, Mezz_Amort = 0, -V18 * Mezz_I_Adj, 1, IPMT(Mezz_I_Adj,IF(T18 = 0, 1, T18),Mezz_Amort_Periods,Mezz_Orig_Loan_Amount)),0)} -> 0 | Z18: =V18+X18 -> 0 | AB18: =IFERROR(ROUNDUP((DATEDIF(Refi_Origination_Date,AD18,"m")+1)/12,0),"") -> 2 | AC18: =IF(AD18<Refi_Begin_PMT,0, AC17+1) -> 13 | AD18: =EDATE(AD17,1) -> 367 | AE18: =IF(AD18>EDATE(DATE(YEAR(Refi_Origination_Date)+ Refi_Amort, MONTH(Refi_Origination_Date), DAY(Refi_Origination_Date)),Refi_Interest_Only),0,AI17) -> 0 | AF18: =AG18+AH18 -> 0 | AG18: =IFERROR(IF(AC18=0,0, PPMT(Refi_I_Adj,'Loan Amort Table'!AC18,Refi_Amort_Periods,Refi_Orig_Loan_Amount)),0) -> 0 | AH18: =IFERROR(IF(Refi_Amort = 0, -AE18 * Refi_I_Adj, IPMT(Refi_I_Adj,IF(AC18 = 0, 1, AC18),Refi_Amort_Periods,Refi_Orig_Loan_Amount)),0) -> 0 | AI18: =AE18+AG18 -> 0
... A500: =IFERROR(ROUNDUP((DATEDIF(SED_Origination_Date,C500,"m")+1)/12,0),"") -> 42 | B500: =IF(C500<SED_Begin_PMT,0, B499+1) -> 495 | C500: =EDATE(C499,1) -> 15036 | D500: =IF(C500>EDATE(DATE(YEAR(SED_Origination_Date)+ SED_Amort, MONTH(SED_Origination_Date), DAY(SED_Origination_Date)),SED_Interest_Only),0,H499) -> 0 | E500: =F500+G500 -> 0 | F500: =IFERROR(IF(OR(B500=0, C500>=Refi_Origination_Date),0, PPMT(SED_I_Adj,'Loan Amort Table'!B500,SED_Amort_Periods,SED_Orig_Loan_Amount)),0) -> 0 | G500: {=IFERROR(_xlfn.IFS(C500>=Refi_Origination_Date, 0, SED_Amort = 0, -D500 * SED_I_Adj, 1, IPMT(SED_I_Adj,IF(B500 = 0, 1, B500),SED_Amort_Periods,SED_Orig_Loan_Amount)),0)} -> 0 | H500: =D500+F500 -> 0 | J500: =IFERROR(ROUNDUP((DATEDIF(NEW_Origination_Date,L500,"m")+1)/12,0),"") -> 42 | K500: =IF(L500<NEW_Begin_PMT,0, K499+1) -> 495 | L500: =EDATE(L499,1) -> 15036 | M500: =IF(L500>EDATE(DATE(YEAR(NEW_Origination_Date)+ NEW_Amort, MONTH(NEW_Origination_Date), DAY(NEW_Origination_Date)),NEW_Interest_Only),0,Q499) -> 0 | N500: =O500+P500 -> 0 | O500: =IFERROR(IF(K500=0,0, PPMT(NEW_I_Adj,'Loan Amort Table'!K500,NEW_Amort_Periods,NEW_Orig_Loan_Amount)),0) -> 0 | P500: =IFERROR(IF(NEW_Amort = 0, -M500* NEW_I_Adj,IPMT(NEW_I_Adj,IF(K500 = 0, 1, K500),NEW_Amort_Periods,NEW_Orig_Loan_Amount)),0) -> 0 | Q500: =M500+O500 -> 0 | S500: =IFERROR(ROUNDUP((DATEDIF(Mezz_Origination_Date,U500,"m")+1)/12,0),"") -> 42 | T500: =IF(U500<Mezz_Begin_PMT,0, T499+1) -> 495 | U500: =EDATE(U499,1) -> 15036 | V500: =IF(U500>EDATE(DATE(YEAR(Mezz_Origination_Date)+ Mezz_Amort, MONTH(Mezz_Origination_Date), DAY(Mezz_Origination_Date)),Mezz_Interest_Only),0,Z499) -> 0 | W500: =X500+Y500 -> 0 | X500: =IFERROR(IF(OR(T500=0, U500>=Refi_Origination_Date),0, PPMT(Mezz_I_Adj,'Loan Amort Table'!T500,Mezz_Amort_Periods,Mezz_Orig_Loan_Amount)),0) -> 0 | Y500: {=IFERROR(_xlfn.IFS(U500>=Refi_Origination_Date,0, Mezz_Amort = 0, -V500 * Mezz_I_Adj, 1, IPMT(Mezz_I_Adj,IF(T500 = 0, 1, T500),Mezz_Amort_Periods,Mezz_Orig_Loan_Amount)),0)} -> 0 | Z500: =V500+X500 -> 0 | AB500: =IFERROR(ROUNDUP((DATEDIF(Refi_Origination_Date,AD500,"m")+1)/12,0),"") -> 42 | AC500: =IF(AD500<Refi_Begin_PMT,0, AC499+1) -> 495 | AD500: =EDATE(AD499,1) -> 15036 | AE500: =IF(AD500>EDATE(DATE(YEAR(Refi_Origination_Date)+ Refi_Amort, MONTH(Refi_Origination_Date), DAY(Refi_Origination_Date)),Refi_Interest_Only),0,AI499) -> 0 | AF500: =AG500+AH500 -> 0 | AG500: =IFERROR(IF(AC500=0,0, PPMT(Refi_I_Adj,'Loan Amort Table'!AC500,Refi_Amort_Periods,Refi_Orig_Loan_Amount)),0) -> 0 | AH500: =IFERROR(IF(Refi_Amort = 0, -AE500 * Refi_I_Adj, IPMT(Refi_I_Adj,IF(AC500 = 0, 1, AC500),Refi_Amort_Periods,Refi_Orig_Loan_Amount)),0) -> 0 | AI500: =AE500+AG500 -> 0
A501: - | B501: - | C501: - | D501: - | E501: - | F501: - | G501: - | H501: - | I501: - | J501: - | K501: - | L501: - | M501: - | N501: - | O501: - | P501: - | Q501: - | S501: - | T501: - | U501: - | V501: - | W501: - | X501: - | Y501: - | Z501: - | AB501: - | AC501: - | AD501: - | AE501: - | AF501: - | AG501: - | AH501: - | AI501: -

Sheet Debt Input
D2: Buyer's Acquisition Financing
D3: Acquisition Financing Type | F3: Financed - New Loan
A4: Navigation Bar | D4: Mezzanine Financing | F4: Yes
A5: Input | D5: Include Refinancing? | F5: Yes
A6: Debt Input | D6: Seller's Existing Debt
A7: Rent Roll Input | D7: Does The Seller Have Existing Debt | F7: No
A12: Equity Returns Input
A13: Rent Roll Detail | D13: DEBT FINANCING | S13: Loan Cash Flow Summary
A14: Rent Roll Summary
A15: Operating Statement | F15: Existing Debt | H15: New Loan | J15: Mezzanine Loan | L15: Refinance Loan | N15: Refinance Loan Options | S15: Year | T15: =EDATE(DATE(YEAR(Date_of_Analysis)+1,MONTH(Date_of_Analysis),DAY(EOMONTH(Date_of_Analysis,0))),-1) -> 366 | U15: =DATE(YEAR(T15)+1, MONTH(T15), 1) -> 701 | V15: =DATE(YEAR(U15)+1, MONTH(U15), 1) -> 1066 | W15: =DATE(YEAR(V15)+1, MONTH(V15), 1) -> 1431 | X15: =DATE(YEAR(W15)+1, MONTH(W15), 1) -> 1797 | Y15: =DATE(YEAR(X15)+1, MONTH(X15), 1) -> 2162 | Z15: =DATE(YEAR(Y15)+1, MONTH(Y15), 1) -> 2527 | AA15: =DATE(YEAR(Z15)+1, MONTH(Z15), 1) -> 2892 | AB15: =DATE(YEAR(AA15)+1, MONTH(AA15), 1) -> 3258 | AC15: =DATE(YEAR(AB15)+1, MONTH(AB15), 1) -> 3623
A16: Notes
A17: Pricing Detail | D17: Loan Name/Type* | N17: Refinance Ballon Amount from Loan(s) | S17: Existing Debt
A18: Growth Rates | D18: Origination Date | H18: =Date_of_Analysis -> 0 | J18: =Date_of_Analysis -> 0 | N18: =IF(L15=0,"","As of "&TEXT(L15,"mmmm-yyyy")&":") -> As of Refinance Loan: | S18: Interest | T18: {=IF(Acq_Financing_Type_Switch = "Financed - Assumed Loan", IFERROR(SUM(_xlfn._xlws.FILTER(INDEX(SED_Table,0,7), (INDEX(SED_Table,0,3) <= T$15) * (INDEX(SED_Table,0,3) >= EDATE(T$15,-12)))),0),0)} -> 0 | U18: {=IF(Acq_Financing_Type_Switch = "Financed - Assumed Loan", IFERROR(SUM(_xlfn._xlws.FILTER(INDEX(SED_Table,0,7), (INDEX(SED_Table,0,3) <= U$15) * (INDEX(SED_Table,0,3) >= EDATE(U$15,-11)))),0),0)} -> 0 | V18: {=IF(Acq_Financing_Type_Switch = "Financed - Assumed Loan", IFERROR(SUM(_xlfn._xlws.FILTER(INDEX(SED_Table,0,7), (INDEX(SED_Table,0,3) <= V$15) * (INDEX(SED_Table,0,3) >= EDATE(V$15,-11)))),0),0)} -> 0 | W18: {=IF(Acq_Financing_Type_Switch = "Financed - Assumed Loan", IFERROR(SUM(_xlfn._xlws.FILTER(INDEX(SED_Table,0,7), (INDEX(SED_Table,0,3) <= W$15) * (INDEX(SED_Table,0,3) >= EDATE(W$15,-11)))),0),0)} -> 0 | X18: {=IF(Acq_Financing_Type_Switch = "Financed - Assumed Loan", IFERROR(SUM(_xlfn._xlws.FILTER(INDEX(SED_Table,0,7), (INDEX(SED_Table,0,3) <= X$15) * (INDEX(SED_Table,0,3) >= EDATE(X$15,-11)))),0),0)} -> 0 | Y18: {=IF(Acq_Financing_Type_Switch = "Financed - Assumed Loan", IFERROR(SUM(_xlfn._xlws.FILTER(INDEX(SED_Table,0,7), (INDEX(SED_Table,0,3) <= Y$15) * (INDEX(SED_Table,0,3) >= EDATE(Y$15,-11)))),0),0)} -> 0 | Z18: {=IF(Acq_Financing_Type_Switch = "Financed - Assumed Loan", IFERROR(SUM(_xlfn._xlws.FILTER(INDEX(SED_Table,0,7), (INDEX(SED_Table,0,3) <= Z$15) * (INDEX(SED_Table,0,3) >= EDATE(Z$15,-11)))),0),0)} -> 0 | AA18: {=IF(Acq_Financing_Type_Switch = "Financed - Assumed Loan", IFERROR(SUM(_xlfn._xlws.FILTER(INDEX(SED_Table,0,7), (INDEX(SED_Table,0,3) <= AA$15) * (INDEX(SED_Table,0,3) >= EDATE(AA$15,-11)))),0),0)} -> 0 | AB18: {=IF(Acq_Financing_Type_Switch = "Financed - Assumed Loan", IFERROR(SUM(_xlfn._xlws.FILTER(INDEX(SED_Table,0,7), (INDEX(SED_Table,0,3) <= AB$15) * (INDEX(SED_Table,0,3) >= EDATE(AB$15,-11)))),0),0)} -> 0 | AC18: {=IF(Acq_Financing_Type_Switch = "Financed - Assumed Loan", IFERROR(SUM(_xlfn._xlws.FILTER(INDEX(SED_Table,0,7), (INDEX(SED_Table,0,3) <= AC$15) * (INDEX(SED_Table,0,3) >= EDATE(AC$15,-11)))),0),0)} -> 0
A19: Cash Flow | D19: Original Loan Amount | H19: =NEW_Orig_Loan_Amount -> 0 | J19: =Mezz_Orig_Loan_Amount -> 0 | L19: =IFERROR(IF(N17="LTV using User Defined Cap Rate on NOI in Year of Refinance", L20*O19,Calculations!E9),0) | N19: =IF(L15=0,"","Asset Value") -> Asset Value | O19: =IFERROR(HLOOKUP(Refi_Origination_Date,'Cash Flow'!G4:P31,26)/O23,"") | S19: Principal | T19: {=IF(Acq_Financing_Type_Switch = "Financed - Assumed Loan", IFERROR(SUM(_xlfn._xlws.FILTER(INDEX(SED_Table,0,6), (INDEX(SED_Table,0,3) <= T$15) * (INDEX(SED_Table,0,3) >= EDATE(T$15,-12)))),0), 0)} -> 0 | U19: {=IF(Acq_Financing_Type_Switch = "Financed - Assumed Loan", IFERROR(SUM(_xlfn._xlws.FILTER(INDEX(SED_Table,0,6), (INDEX(SED_Table,0,3) <= U$15) * (INDEX(SED_Table,0,3) >= EDATE(U$15,-11)))),0), 0)} -> 0 | V19: {=IF(Acq_Financing_Type_Switch = "Financed - Assumed Loan", IFERROR(SUM(_xlfn._xlws.FILTER(INDEX(SED_Table,0,6), (INDEX(SED_Table,0,3) <= V$15) * (INDEX(SED_Table,0,3) >= EDATE(V$15,-11)))),0), 0)} -> 0 | W19: {=IF(Acq_Financing_Type_Switch = "Financed - Assumed Loan", IFERROR(SUM(_xlfn._xlws.FILTER(INDEX(SED_Table,0,6), (INDEX(SED_Table,0,3) <= W$15) * (INDEX(SED_Table,0,3) >= EDATE(W$15,-11)))),0), 0)} -> 0 | X19: {=IF(Acq_Financing_Type_Switch = "Financed - Assumed Loan", IFERROR(SUM(_xlfn._xlws.FILTER(INDEX(SED_Table,0,6), (INDEX(SED_Table,0,3) <= X$15) * (INDEX(SED_Table,0,3) >= EDATE(X$15,-11)))),0), 0)} -> 0 | Y19: {=IF(Acq_Financing_Type_Switch = "Financed - Assumed Loan", IFERROR(SUM(_xlfn._xlws.FILTER(INDEX(SED_Table,0,6), (INDEX(SED_Table,0,3) <= Y$15) * (INDEX(SED_Table,0,3) >= EDATE(Y$15,-11)))),0), 0)} -> 0 | Z19: {=IF(Acq_Financing_Type_Switch = "Financed - Assumed Loan", IFERROR(SUM(_xlfn._xlws.FILTER(INDEX(SED_Table,0,6), (INDEX(SED_Table,0,3) <= Z$15) * (INDEX(SED_Table,0,3) >= EDATE(Z$15,-11)))),0), 0)} -> 0 | AA19: {=IF(Acq_Financing_Type_Switch = "Financed - Assumed Loan", IFERROR(SUM(_xlfn._xlws.FILTER(INDEX(SED_Table,0,6), (INDEX(SED_Table,0,3) <= AA$15) * (INDEX(SED_Table,0,3) >= EDATE(AA$15,-11)))),0), 0)} -> 0 | AB19: {=IF(Acq_Financing_Type_Switch = "Financed - Assumed Loan", IFERROR(SUM(_xlfn._xlws.FILTER(INDEX(SED_Table,0,6), (INDEX(SED_Table,0,3) <= AB$15) * (INDEX(SED_Table,0,3) >= EDATE(AB$15,-11)))),0), 0)} -> 0 | AC19: {=IF(Acq_Financing_Type_Switch = "Financed - Assumed Loan", IFERROR(SUM(_xlfn._xlws.FILTER(INDEX(SED_Table,0,6), (INDEX(SED_Table,0,3) <= AC$15) * (INDEX(SED_Table,0,3) >= EDATE(AC$15,-11)))),0), 0)} -> 0
A20: Proposal Price IRR | D20: LTV | F20: =SED_Orig_Loan_Amount/sale_price -> #DIV/0! | N20: =IF(L15=0,"","Existing Debt") -> Existing Debt | O20: =Calculations!E9 | P20: =IFERROR(VLOOKUP(DATE(YEAR(Refi_Origination_Date),MONTH(Refi_Origination_Date),1),'Loan Amort Table'!AD6:AI500,6),"") -> 0 | S20: New Loan
A21: Equity Returns Options | D21: Loan Balance | F21: =SED_Loan_Balance -> 0 | H21: =NEW_Loan_Balance -> 0 | J21: =Mezz_Loan_Balance -> 0 | L21: =Refi_Loan_Balance -> 0 | N21: =IF(L15=0,"","LTV") -> LTV | O21: =IFERROR(O20/O19,"") | S21: Interest | T21: {=IF(Acq_Financing_Type_Switch = "Financed - New Loan", IFERROR(SUM(_xlfn._xlws.FILTER(INDEX(NEW_Table,0,7), (INDEX(NEW_Table,0,3) <= T$15) * (INDEX(NEW_Table,0,3) >= EDATE(T$15,-12)))),0), 0)} -> 0 | U21: {=IF(Acq_Financing_Type_Switch = "Financed - New Loan", IFERROR(SUM(_xlfn._xlws.FILTER(INDEX(NEW_Table,0,7), (INDEX(NEW_Table,0,3) <= U$15) * (INDEX(NEW_Table,0,3) >= EDATE(U$15,-11)))),0), 0)} -> 0 | V21: {=IF(Acq_Financing_Type_Switch = "Financed - New Loan", IFERROR(SUM(_xlfn._xlws.FILTER(INDEX(NEW_Table,0,7), (INDEX(NEW_Table,0,3) <= V$15) * (INDEX(NEW_Table,0,3) >= EDATE(V$15,-11)))),0), 0)} -> 0 | W21: {=IF(Acq_Financing_Type_Switch = "Financed - New Loan", IFERROR(SUM(_xlfn._xlws.FILTER(INDEX(NEW_Table,0,7), (INDEX(NEW_Table,0,3) <= W$15) * (INDEX(NEW_Table,0,3) >= EDATE(W$15,-11)))),0), 0)} -> 0 | X21: {=IF(Acq_Financing_Type_Switch = "Financed - New Loan", IFERROR(SUM(_xlfn._xlws.FILTER(INDEX(NEW_Table,0,7), (INDEX(NEW_Table,0,3) <= X$15) * (INDEX(NEW_Table,0,3) >= EDATE(X$15,-11)))),0), 0)} -> 0 | Y21: {=IF(Acq_Financing_Type_Switch = "Financed - New Loan", IFERROR(SUM(_xlfn._xlws.FILTER(INDEX(NEW_Table,0,7), (INDEX(NEW_Table,0,3) <= Y$15) * (INDEX(NEW_Table,0,3) >= EDATE(Y$15,-11)))),0), 0)} -> 0 | Z21: {=IF(Acq_Financing_Type_Switch = "Financed - New Loan", IFERROR(SUM(_xlfn._xlws.FILTER(INDEX(NEW_Table,0,7), (INDEX(NEW_Table,0,3) <= Z$15) * (INDEX(NEW_Table,0,3) >= EDATE(Z$15,-11)))),0), 0)} -> 0 | AA21: {=IF(Acq_Financing_Type_Switch = "Financed - New Loan", IFERROR(SUM(_xlfn._xlws.FILTER(INDEX(NEW_Table,0,7), (INDEX(NEW_Table,0,3) <= AA$15) * (INDEX(NEW_Table,0,3) >= EDATE(AA$15,-11)))),0), 0)} -> 0 | AB21: {=IF(Acq_Financing_Type_Switch = "Financed - New Loan", IFERROR(SUM(_xlfn._xlws.FILTER(INDEX(NEW_Table,0,7), (INDEX(NEW_Table,0,3) <= AB$15) * (INDEX(NEW_Table,0,3) >= EDATE(AB$15,-11)))),0), 0)} -> 0 | AC21: {=IF(Acq_Financing_Type_Switch = "Financed - New Loan", IFERROR(SUM(_xlfn._xlws.FILTER(INDEX(NEW_Table,0,7), (INDEX(NEW_Table,0,3) <= AC$15) * (INDEX(NEW_Table,0,3) >= EDATE(AC$15,-11)))),0), 0)} -> 0
A22: Equity Returns Chart | D22: Interest Rate | N22: =IF(L15=0,"","DSCR") -> DSCR | O22: =IFERROR(HLOOKUP(Refi_Origination_Date,'Cash Flow'!G4:P31,26)/-L31,"") | S22: Principal | T22: {=IF(Acq_Financing_Type_Switch = "Financed - New Loan", IFERROR(SUM(_xlfn._xlws.FILTER(INDEX(NEW_Table,0,6), (INDEX(NEW_Table,0,3) <= T$15) * (INDEX(NEW_Table,0,3) >= EDATE(T$15,-12)))),0), 0)} -> 0 | U22: {=IF(Acq_Financing_Type_Switch = "Financed - New Loan", IFERROR(SUM(_xlfn._xlws.FILTER(INDEX(NEW_Table,0,6), (INDEX(NEW_Table,0,3) <= U$15) * (INDEX(NEW_Table,0,3) >= EDATE(U$15,-11)))),0), 0)} -> 0 | V22: {=IF(Acq_Financing_Type_Switch = "Financed - New Loan", IFERROR(SUM(_xlfn._xlws.FILTER(INDEX(NEW_Table,0,6), (INDEX(NEW_Table,0,3) <= V$15) * (INDEX(NEW_Table,0,3) >= EDATE(V$15,-11)))),0), 0)} -> 0 | W22: {=IF(Acq_Financing_Type_Switch = "Financed - New Loan", IFERROR(SUM(_xlfn._xlws.FILTER(INDEX(NEW_Table,0,6), (INDEX(NEW_Table,0,3) <= W$15) * (INDEX(NEW_Table,0,3) >= EDATE(W$15,-11)))),0), 0)} -> 0 | X22: {=IF(Acq_Financing_Type_Switch = "Financed - New Loan", IFERROR(SUM(_xlfn._xlws.FILTER(INDEX(NEW_Table,0,6), (INDEX(NEW_Table,0,3) <= X$15) * (INDEX(NEW_Table,0,3) >= EDATE(X$15,-11)))),0), 0)} -> 0 | Y22: {=IF(Acq_Financing_Type_Switch = "Financed - New Loan", IFERROR(SUM(_xlfn._xlws.FILTER(INDEX(NEW_Table,0,6), (INDEX(NEW_Table,0,3) <= Y$15) * (INDEX(NEW_Table,0,3) >= EDATE(Y$15,-11)))),0), 0)} -> 0 | Z22: {=IF(Acq_Financing_Type_Switch = "Financed - New Loan", IFERROR(SUM(_xlfn._xlws.FILTER(INDEX(NEW_Table,0,6), (INDEX(NEW_Table,0,3) <= Z$15) * (INDEX(NEW_Table,0,3) >= EDATE(Z$15,-11)))),0), 0)} -> 0 | AA22: {=IF(Acq_Financing_Type_Switch = "Financed - New Loan", IFERROR(SUM(_xlfn._xlws.FILTER(INDEX(NEW_Table,0,6), (INDEX(NEW_Table,0,3) <= AA$15) * (INDEX(NEW_Table,0,3) >= EDATE(AA$15,-11)))),0), 0)} -> 0 | AB22: {=IF(Acq_Financing_Type_Switch = "Financed - New Loan", IFERROR(SUM(_xlfn._xlws.FILTER(INDEX(NEW_Table,0,6), (INDEX(NEW_Table,0,3) <= AB$15) * (INDEX(NEW_Table,0,3) >= EDATE(AB$15,-11)))),0), 0)} -> 0 | AC22: {=IF(Acq_Financing_Type_Switch = "Financed - New Loan", IFERROR(SUM(_xlfn._xlws.FILTER(INDEX(NEW_Table,0,6), (INDEX(NEW_Table,0,3) <= AC$15) * (INDEX(NEW_Table,0,3) >= EDATE(AC$15,-11)))),0), 0)} -> 0
D23: Compounding | N23: Cap Rate at Refi | S23: Mezzanine Loan
D24: Term (Years) | J24: =Mezz_Term -> #NUM! | S24: Interest | T24: {=IF(Mezz_Switch = "Yes", IFERROR(SUM(_xlfn._xlws.FILTER(INDEX(Mezz_Table,0,7), (INDEX(Mezz_Table,0,3) <= T$15) * (INDEX(Mezz_Table,0,3) >= EDATE(T$15,-12)))),0), 0)} -> 0 | U24: {=IF(Mezz_Switch = "Yes", IFERROR(SUM(_xlfn._xlws.FILTER(INDEX(Mezz_Table,0,7), (INDEX(Mezz_Table,0,3) <= U$15) * (INDEX(Mezz_Table,0,3) >= EDATE(U$15,-11)))),0), 0)} -> 0 | V24: {=IF(Mezz_Switch = "Yes", IFERROR(SUM(_xlfn._xlws.FILTER(INDEX(Mezz_Table,0,7), (INDEX(Mezz_Table,0,3) <= V$15) * (INDEX(Mezz_Table,0,3) >= EDATE(V$15,-11)))),0), 0)} -> 0 | W24: {=IF(Mezz_Switch = "Yes", IFERROR(SUM(_xlfn._xlws.FILTER(INDEX(Mezz_Table,0,7), (INDEX(Mezz_Table,0,3) <= W$15) * (INDEX(Mezz_Table,0,3) >= EDATE(W$15,-11)))),0), 0)} -> 0 | X24: {=IF(Mezz_Switch = "Yes", IFERROR(SUM(_xlfn._xlws.FILTER(INDEX(Mezz_Table,0,7), (INDEX(Mezz_Table,0,3) <= X$15) * (INDEX(Mezz_Table,0,3) >= EDATE(X$15,-11)))),0), 0)} -> 0 | Y24: {=IF(Mezz_Switch = "Yes", IFERROR(SUM(_xlfn._xlws.FILTER(INDEX(Mezz_Table,0,7), (INDEX(Mezz_Table,0,3) <= Y$15) * (INDEX(Mezz_Table,0,3) >= EDATE(Y$15,-11)))),0), 0)} -> 0 | Z24: {=IF(Mezz_Switch = "Yes", IFERROR(SUM(_xlfn._xlws.FILTER(INDEX(Mezz_Table,0,7), (INDEX(Mezz_Table,0,3) <= Z$15) * (INDEX(Mezz_Table,0,3) >= EDATE(Z$15,-11)))),0), 0)} -> 0 | AA24: {=IF(Mezz_Switch = "Yes", IFERROR(SUM(_xlfn._xlws.FILTER(INDEX(Mezz_Table,0,7), (INDEX(Mezz_Table,0,3) <= AA$15) * (INDEX(Mezz_Table,0,3) >= EDATE(AA$15,-11)))),0), 0)} -> 0 | AB24: {=IF(Mezz_Switch = "Yes", IFERROR(SUM(_xlfn._xlws.FILTER(INDEX(Mezz_Table,0,7), (INDEX(Mezz_Table,0,3) <= AB$15) * (INDEX(Mezz_Table,0,3) >= EDATE(AB$15,-11)))),0), 0)} -> 0 | AC24: {=IF(Mezz_Switch = "Yes", IFERROR(SUM(_xlfn._xlws.FILTER(INDEX(Mezz_Table,0,7), (INDEX(Mezz_Table,0,3) <= AC$15) * (INDEX(Mezz_Table,0,3) >= EDATE(AC$15,-11)))),0), 0)} -> 0
